<?xml version="1.0" encoding="utf-8"?>
<!-- =================================================================================== -->
<!-- |    This document was autogenerated by xacro from arm.xacro                      | -->
<!-- |    EDITING THIS FILE BY HAND IS NOT RECOMMENDED                                 | -->
<!-- =================================================================================== -->
<robot name="arm">
  <material name="Black">
    <color rgba="0 0 0 1"/>
  </material>
  <material name="White">
    <color rgba="1 1 1 1"/>
  </material>
  <material name="Blue">
    <color rgba="0 0 1 1"/>
  </material>
  <material name="Red">
    <color rgba="1 0 0 1"/>
  </material>
  <!--*************************************************************-->
  <!--*************************************************************-->
  <!--*************************************************************-->
  <link name="base_link">
    <visual>
      <origin rpy="0 0 0" xyz="0 0 0"/>
      <geometry>
        <box size="0.15 0.15 0.01"/>
      </geometry>
      <material name="Black"/>
    </visual>
    <collision>
      <origin rpy="0 0 0" xyz="0 0 0"/>
      <geometry>
        <box size="0.15 0.15 0.01"/>
      </geometry>
    </collision>
    <inertial>
      <mass value="10"/>
      <inertia ixx="0.0188333333333" ixy="0" ixz="0" iyy="0.0188333333333" iyz="0" izz="0.0375"/>
    </inertial>
  </link>
  <gazebo reference="base_link">
    <material>Gazebo/Black</material>
  </gazebo>
  <link name="base_joint">
    <visual>
      <origin rpy="0 0 0" xyz="0 0 0"/>
      <geometry>
        <box size="0.05 0.07 0.07"/>
      </geometry>
      <material name="Black"/>
    </visual>
    <collision>
      <origin rpy="0 0 0" xyz="0 0 0"/>
      <geometry>
        <box size="0.05 0.07 0.07"/>
      </geometry>
    </collision>
    <inertial>
      <mass value="0.1"/>
      <inertia ixx="8.16666666667e-05" ixy="0" ixz="0" iyy="6.16666666667e-05" iyz="0" izz="6.16666666667e-05"/>
    </inertial>
  </link>
  <gazebo reference="base_joint">
    <material>Gazebo/Black</material>
  </gazebo>
  <joint name="base_link_to_base_joint" type="continuous">
    <origin rpy="0 0 0" xyz="0 0 0.04"/>
    <parent link="base_link"/>
    <child link="base_joint"/>
    <axis xyz="0 0 1"/>
  </joint>
  <link name="first_arm_joint_right">
    <visual>
      <origin rpy="0 0 0" xyz="0 0 0"/>
      <geometry>
        <cylinder length="0.02" radius="0.03"/>
      </geometry>
      <material name="Blue"/>
    </visual>
    <collision>
      <origin rpy="0 0 0" xyz="0 0 0"/>
      <geometry>
        <cylinder length="0.02" radius="0.03"/>
      </geometry>
    </collision>
    <inertial>
      <mass value="0.05"/>
      <inertia ixx="1.29166666667e-05" ixy="0" ixz="0" iyy="1.29166666667e-05" iyz="0" izz="2.25e-05"/>
    </inertial>
  </link>
  <gazebo reference="first_arm_joint_right">
    <material>Gazebo/Blue</material>
  </gazebo>
  <joint name="base_joint_to_first_arm_joint_right" type="continuous">
    <origin rpy="0 1.5707963 0" xyz="-0.035 0 0"/>
    <parent link="base_joint"/>
    <child link="first_arm_joint_right"/>
    <axis xyz="0 0 1"/>
  </joint>
  <link name="first_arm_right">
    <visual>
      <origin rpy="0 0 0" xyz="0 0 0"/>
      <geometry>
        <box size="0.02 0.06 0.25"/>
      </geometry>
      <material name="White"/>
    </visual>
    <collision>
      <origin rpy="0 0 0" xyz="0 0 0"/>
      <geometry>
        <box size="0.02 0.06 0.25"/>
      </geometry>
    </collision>
    <inertial>
      <mass value="0.2"/>
      <inertia ixx="0.00110166666667" ixy="0" ixz="0" iyy="0.00104833333333" iyz="0" izz="6.66666666667e-05"/>
    </inertial>
  </link>
  <gazebo reference="first_arm_right">
    <material>Gazebo/White</material>
  </gazebo>
  <joint name="first_arm_joint_right_to_first_arm_right" type="fixed">
    <origin rpy="0 1.5707963 0" xyz="-0.125 0 0"/>
    <parent link="first_arm_joint_right"/>
    <child link="first_arm_right"/>
  </joint>
  <link name="first_joint">
    <visual>
      <origin rpy="0 0 0" xyz="0 0 0"/>
      <geometry>
        <box size="0.05 0.07 0.07"/>
      </geometry>
      <material name="Black"/>
    </visual>
    <collision>
      <origin rpy="0 0 0" xyz="0 0 0"/>
      <geometry>
        <box size="0.05 0.07 0.07"/>
      </geometry>
    </collision>
    <inertial>
      <mass value="0.1"/>
      <inertia ixx="8.16666666667e-05" ixy="0" ixz="0" iyy="6.16666666667e-05" iyz="0" izz="6.16666666667e-05"/>
    </inertial>
  </link>
  <gazebo reference="first_joint">
    <material>Gazebo/Black</material>
  </gazebo>
  <joint name="first_arm_right_to_first_joint" type="fixed">
    <origin rpy="0 0 0" xyz="-0.035 0 -0.125"/>
    <parent link="first_arm_right"/>
    <child link="first_joint"/>
  </joint>
  <link name="second_arm_joint_right">
    <visual>
      <origin rpy="0 0 0" xyz="0 0 0"/>
      <geometry>
        <cylinder length="0.02" radius="0.03"/>
      </geometry>
      <material name="Blue"/>
    </visual>
    <collision>
      <origin rpy="0 0 0" xyz="0 0 0"/>
      <geometry>
        <cylinder length="0.02" radius="0.03"/>
      </geometry>
    </collision>
    <inertial>
      <mass value="0.05"/>
      <inertia ixx="1.29166666667e-05" ixy="0" ixz="0" iyy="1.29166666667e-05" iyz="0" izz="2.25e-05"/>
    </inertial>
  </link>
  <gazebo reference="second_arm_joint_right">
    <material>Gazebo/Blue</material>
  </gazebo>
  <joint name="first_joint_to_second_arm_joint_right" type="continuous">
    <origin rpy="0 1.5707963 0" xyz="-0.035 0 0"/>
    <parent link="first_joint"/>
    <child link="second_arm_joint_right"/>
    <axis xyz="0 0 1"/>
  </joint>
  <link name="second_arm_right">
    <visual>
      <origin rpy="0 0 0" xyz="0 0 0"/>
      <geometry>
        <box size="0.02 0.06 0.25"/>
      </geometry>
      <material name="White"/>
    </visual>
    <collision>
      <origin rpy="0 0 0" xyz="0 0 0"/>
      <geometry>
        <box size="0.02 0.06 0.25"/>
      </geometry>
    </collision>
    <inertial>
      <mass value="0.2"/>
      <inertia ixx="0.00110166666667" ixy="0" ixz="0" iyy="0.00104833333333" iyz="0" izz="6.66666666667e-05"/>
    </inertial>
  </link>
  <gazebo reference="second_arm_right">
    <material>Gazebo/White</material>
  </gazebo>
  <joint name="second_arm_joint_right_to_second_arm_right" type="fixed">
    <origin rpy="0 1.5707963 0" xyz="0.125 0 0"/>
    <parent link="second_arm_joint_right"/>
    <child link="second_arm_right"/>
  </joint>
  <link name="second_joint">
    <visual>
      <origin rpy="0 0 0" xyz="0 0 0"/>
      <geometry>
        <box size="0.05 0.07 0.07"/>
      </geometry>
      <material name="Black"/>
    </visual>
    <collision>
      <origin rpy="0 0 0" xyz="0 0 0"/>
      <geometry>
        <box size="0.05 0.07 0.07"/>
      </geometry>
    </collision>
    <inertial>
      <mass value="0.1"/>
      <inertia ixx="8.16666666667e-05" ixy="0" ixz="0" iyy="6.16666666667e-05" iyz="0" izz="6.16666666667e-05"/>
    </inertial>
  </link>
  <gazebo reference="second_joint">
    <material>Gazebo/Black</material>
  </gazebo>
  <joint name="second_arm_right_to_second_joint" type="fixed">
    <origin rpy="0 0 0" xyz="-0.035 0 0.125"/>
    <parent link="second_arm_right"/>
    <child link="second_joint"/>
  </joint>
  <link name="third_arm_joint_right">
    <visual>
      <origin rpy="0 0 0" xyz="0 0 0"/>
      <geometry>
        <cylinder length="0.02" radius="0.03"/>
      </geometry>
      <material name="Blue"/>
    </visual>
    <collision>
      <origin rpy="0 0 0" xyz="0 0 0"/>
      <geometry>
        <cylinder length="0.02" radius="0.03"/>
      </geometry>
    </collision>
    <inertial>
      <mass value="0.05"/>
      <inertia ixx="1.29166666667e-05" ixy="0" ixz="0" iyy="1.29166666667e-05" iyz="0" izz="2.25e-05"/>
    </inertial>
  </link>
  <gazebo reference="third_arm_joint_right">
    <material>Gazebo/Blue</material>
  </gazebo>
  <joint name="second_joint_to_third_arm_joint_right" type="continuous">
    <origin rpy="0 1.5707963 0" xyz="-0.035 0 0"/>
    <parent link="second_joint"/>
    <child link="third_arm_joint_right"/>
    <axis xyz="0 0 1"/>
  </joint>
  <link name="third_arm_right">
    <visual>
      <origin rpy="0 0 0" xyz="0 0 0"/>
      <geometry>
        <box size="0.02 0.06 0.25"/>
      </geometry>
      <material name="White"/>
    </visual>
    <collision>
      <origin rpy="0 0 0" xyz="0 0 0"/>
      <geometry>
        <box size="0.02 0.06 0.25"/>
      </geometry>
    </collision>
    <inertial>
      <mass value="0.2"/>
      <inertia ixx="0.00110166666667" ixy="0" ixz="0" iyy="0.00104833333333" iyz="0" izz="6.66666666667e-05"/>
    </inertial>
  </link>
  <gazebo reference="third_arm_right">
    <material>Gazebo/White</material>
  </gazebo>
  <joint name="third_arm_joint_right_to_third_arm_right" type="fixed">
    <origin rpy="0 1.5707963 0" xyz="-0.125 0 0"/>
    <parent link="third_arm_joint_right"/>
    <child link="third_arm_right"/>
  </joint>
  <link name="third_joint">
    <visual>
      <origin rpy="0 0 0" xyz="0 0 0"/>
      <geometry>
        <box size="0.05 0.07 0.07"/>
      </geometry>
      <material name="Black"/>
    </visual>
    <collision>
      <origin rpy="0 0 0" xyz="0 0 0"/>
      <geometry>
        <box size="0.05 0.07 0.07"/>
      </geometry>
    </collision>
    <inertial>
      <mass value="0.1"/>
      <inertia ixx="8.16666666667e-05" ixy="0" ixz="0" iyy="6.16666666667e-05" iyz="0" izz="6.16666666667e-05"/>
    </inertial>
  </link>
  <gazebo reference="third_joint">
    <material>Gazebo/Black</material>
  </gazebo>
  <joint name="third_arm_right_to_third_joint" type="fixed">
    <origin rpy="0 0 0" xyz="-0.035 0 -0.125"/>
    <parent link="third_arm_right"/>
    <child link="third_joint"/>
  </joint>
  <link name="zhuazi_base">
    <visual>
      <origin rpy="0 0 0" xyz="0 0 0"/>
      <geometry>
        <box size="0.1 0.07 0.02"/>
      </geometry>
      <material name="Blue"/>
    </visual>
    <collision>
      <origin rpy="0 0 0" xyz="0 0 0"/>
      <geometry>
        <box size="0.1 0.07 0.02"/>
      </geometry>
    </collision>
    <inertial>
      <mass value="0.1"/>
      <inertia ixx="4.41666666667e-05" ixy="0" ixz="0" iyy="8.66666666667e-05" iyz="0" izz="0.000124166666667"/>
    </inertial>
  </link>
  <gazebo reference="zhuazi_base">
    <material>Gazebo/Blue</material>
  </gazebo>
  <joint name="third_joint_to_zhuazi_base" type="fixed">
    <origin rpy="0 0 0" xyz="0 0 -0.045"/>
    <parent link="third_joint"/>
    <child link="zhuazi_base"/>
  </joint>
  <link name="zhuazi_left">
    <visual>
      <origin rpy="0 0 0" xyz="0 0 0"/>
      <geometry>
        <box size="0.005 0.04 0.07"/>
      </geometry>
      <material name="Red"/>
    </visual>
    <collision>
      <origin rpy="0 0 0" xyz="0 0 0"/>
      <geometry>
        <box size="0.005 0.04 0.07"/>
      </geometry>
    </collision>
    <inertial>
      <mass value="0.05"/>
      <inertia ixx="2.70833333333e-05" ixy="0" ixz="0" iyy="2.05208333333e-05" iyz="0" izz="6.77083333333e-06"/>
    </inertial>
  </link>
  <gazebo reference="zhuazi_left">
    <material>Gazebo/Red</material>
  </gazebo>
  <joint name="zhuazi_base_to_zhuazi_left" type="prismatic">
    <origin rpy="0 0 0" xyz="0.03 0 -0.045"/>
    <parent link="zhuazi_base"/>
    <child link="zhuazi_left"/>
    <axis xyz="1 0 0"/>
    <limit effort="100" lower="0" upper="100" velocity="100"/>
  </joint>
  <link name="zhuazi_right">
    <visual>
      <origin rpy="0 0 0" xyz="0 0 0"/>
      <geometry>
        <box size="0.005 0.04 0.07"/>
      </geometry>
      <material name="Red"/>
    </visual>
    <collision>
      <origin rpy="0 0 0" xyz="0 0 0"/>
      <geometry>
        <box size="0.005 0.04 0.07"/>
      </geometry>
    </collision>
    <inertial>
      <mass value="0.05"/>
      <inertia ixx="2.70833333333e-05" ixy="0" ixz="0" iyy="2.05208333333e-05" iyz="0" izz="6.77083333333e-06"/>
    </inertial>
  </link>
  <gazebo reference="zhuazi_right">
    <material>Gazebo/Red</material>
  </gazebo>
  <joint name="zhuazi_base_to_zhuazi_right" type="prismatic">
    <origin rpy="0 0 0" xyz="-0.03 0 -0.045"/>
    <parent link="zhuazi_base"/>
    <child link="zhuazi_right"/>
    <axis xyz="1 0 0"/>
    <limit effort="100" lower="0" upper="100" velocity="100"/>
  </joint>
  <transmission name="base_link_to_base_joint">
    <type>transmission_interface/SimpleTransmission</type>
    <joint name="base_link_to_base_joint">
      <hardwareInterface>hardware_interface/PositionJointInterface</hardwareInterface>
    </joint>
    <actuator name="base_link">
      <hardwareInterface>PositionJointInterface</hardwareInterface>
      <mechanicalReduction>1</mechanicalReduction>
    </actuator>
  </transmission>
  <transmission name="base_joint_to_first_arm_joint_right">
    <type>transmission_interface/SimpleTransmission</type>
    <joint name="base_joint_to_first_arm_joint_right">
      <hardwareInterface>hardware_interface/PositionJointInterface</hardwareInterface>
    </joint>
    <actuator name="base_joint">
      <hardwareInterface>PositionJointInterface</hardwareInterface>
      <mechanicalReduction>1</mechanicalReduction>
    </actuator>
  </transmission>
  <transmission name="first_joint_to_second_arm_joint_right">
    <type>transmission_interface/SimpleTransmission</type>
    <joint name="first_joint_to_second_arm_joint_right">
      <hardwareInterface>hardware_interface/PositionJointInterface</hardwareInterface>
    </joint>
    <actuator name="first_joint">
      <hardwareInterface>PositionJointInterface</hardwareInterface>
      <mechanicalReduction>1</mechanicalReduction>
    </actuator>
  </transmission>
  <transmission name="second_joint_to_third_arm_joint_right">
    <type>transmission_interface/SimpleTransmission</type>
    <joint name="second_joint_to_third_arm_joint_right">
      <hardwareInterface>hardware_interface/PositionJointInterface</hardwareInterface>
    </joint>
    <actuator name="second_joint">
      <hardwareInterface>PositionJointInterface</hardwareInterface>
      <mechanicalReduction>1</mechanicalReduction>
    </actuator>
  </transmission>
  <transmission name="zhuazi_base_to_zhuazi_left">
    <type>transmission_interface/SimpleTransmission</type>
    <joint name="zhuazi_base_to_zhuazi_left">
      <hardwareInterface>hardware_interface/PositionJointInterface</hardwareInterface>
    </joint>
    <actuator name="zhuazi_base">
      <hardwareInterface>PositionJointInterface</hardwareInterface>
      <mechanicalReduction>1</mechanicalReduction>
    </actuator>
  </transmission>
  <transmission name="zhuazi_base_to_zhuazi_right">
    <type>transmission_interface/SimpleTransmission</type>
    <joint name="zhuazi_base_to_zhuazi_right">
      <hardwareInterface>hardware_interface/PositionJointInterface</hardwareInterface>
    </joint>
    <actuator name="zhuazi_base">
      <hardwareInterface>PositionJointInterface</hardwareInterface>
      <mechanicalReduction>1</mechanicalReduction>
    </actuator>
  </transmission>
  <gazebo>
    <plugin filename="libgazebo_ros_control.so" name="gazebo_ros_control">
      <robotNamespace>/mechnical_arm_DC</robotNamespace>
    </plugin>
  </gazebo>
</robot>

